Workbook

Sheet Olawale_conf ALL wells
B2: 178837 | C2: 11210 | D2: 15267 | E2: 281 | F2: 0 | G2: 1054 | H2: 1 | I2: 0 | J2: 0 | K2: 288 | L2: 92 | M2: 0 | O2: =SUM(B2:M13) -> 1429694 | R2: =B2/$O$2*100 -> 12.508761 | S2: =C2/$O$2*100 -> 0.78408387 | T2: =D2/$O$2*100 -> 1.0678509 | U2: =E2/$O$2*100 -> 0.019654555 | V2: =F2/$O$2*100 -> 0 | W2: =G2/$O$2*100 -> 0.073722069 | X2: =H2/$O$2*100 -> 6.9945037e-05 | Y2: =I2/$O$2*100 -> 0 | ... AC2: =M2/$O$2*100 -> 0
B3: 17277 | C3: 113170 | D3: 48482 | E3: 438 | F3: 0 | G3: 518 | H3: 0 | I3: 0 | J3: 0 | K3: 301 | L3: 110 | M3: 0 | R3: =B3/$O$2*100 -> 1.2084404 | S3: =C3/$O$2*100 -> 7.9156799 | T3: =D3/$O$2*100 -> 3.3910753 | U3: =E3/$O$2*100 -> 0.030635926 | V3: =F3/$O$2*100 -> 0 | W3: =G3/$O$2*100 -> 0.036231529 | X3: =H3/$O$2*100 -> 0 | Y3: =I3/$O$2*100 -> 0 | ... AC3: =M3/$O$2*100 -> 0
B4: 6292 | C4: 12937 | D4: 849536 | E4: 3154 | F4: 15 | G4: 2432 | H4: 109 | I4: 65 | J4: 17 | K4: 1831 | L4: 217 | M4: 0 | R4: =B4/$O$2*100 -> 0.44009417 | S4: =C4/$O$2*100 -> 0.90487895 | T4: =D4/$O$2*100 -> 59.420827 | U4: =E4/$O$2*100 -> 0.22060665 | V4: =F4/$O$2*100 -> 0.0010491756 | W4: =G4/$O$2*100 -> 0.17010633 | X4: =H4/$O$2*100 -> 0.0076240091 | Y4: =I4/$O$2*100 -> 0.0045464274 | ... AC4: =M4/$O$2*100 -> 0
B5: 494 | C5: 1133 | D5: 8191 | E5: 26635 | F5: 0 | G5: 4250 | H5: 325 | I5: 0 | J5: 0 | K5: 1 | L5: 2 | M5: 0 | R5: =B5/$O$2*100 -> 0.034552848 | S5: =C5/$O$2*100 -> 0.079247727 | T5: =D5/$O$2*100 -> 0.5729198 | U5: =E5/$O$2*100 -> 1.8629861 | V5: =F5/$O$2*100 -> 0 | W5: =G5/$O$2*100 -> 0.29726641 | X5: =H5/$O$2*100 -> 0.022732137 | Y5: =I5/$O$2*100 -> 0 | ... AC5: =M5/$O$2*100 -> 0
B6: 143 | C6: 123 | D6: 1537 | E6: 17 | F6: 100 | G6: 293 | H6: 0 | I6: 2 | J6: 174 | K6: 2 | L6: 0 | M6: 0 | R6: =B6/$O$2*100 -> 0.01000214 | S6: =C6/$O$2*100 -> 0.0086032396 | T6: =D6/$O$2*100 -> 0.10750552 | U6: =E6/$O$2*100 -> 0.0011890656 | V6: =F6/$O$2*100 -> 0.0069945037 | W6: =G6/$O$2*100 -> 0.020493896 | X6: =H6/$O$2*100 -> 0 | Y6: =I6/$O$2*100 -> 0.00013989007 | ... AC6: =M6/$O$2*100 -> 0
B7: 3710 | C7: 2334 | D7: 11808 | E7: 2984 | F7: 1 | G7: 47190 | H7: 858 | I7: 0 | J7: 27 | K7: 580 | L7: 0 | M7: 0 | R7: =B7/$O$2*100 -> 0.25949609 | S7: =C7/$O$2*100 -> 0.16325172 | T7: =D7/$O$2*100 -> 0.825911 | U7: =E7/$O$2*100 -> 0.20871599 | V7: =F7/$O$2*100 -> 6.9945037e-05 | W7: =G7/$O$2*100 -> 3.3007063 | X7: =H7/$O$2*100 -> 0.060012842 | Y7: =I7/$O$2*100 -> 0 | ... AC7: =M7/$O$2*100 -> 0
B8: 87 | C8: 0 | D8: 6 | E8: 60 | F8: 0 | G8: 3236 | H8: 10654 | I8: 0 | J8: 0 | K8: 0 | L8: 0 | M8: 0 | R8: =B8/$O$2*100 -> 0.0060852182 | S8: =C8/$O$2*100 -> 0 | T8: =D8/$O$2*100 -> 0.00041967022 | U8: =E8/$O$2*100 -> 0.0041967022 | V8: =F8/$O$2*100 -> 0 | W8: =G8/$O$2*100 -> 0.22634214 | X8: =H8/$O$2*100 -> 0.74519443 | Y8: =I8/$O$2*100 -> 0 | ... AC8: =M8/$O$2*100 -> 0
B9: 1 | C9: 0 | D9: 60 | E9: 0 | F9: 3 | G9: 4 | H9: 0 | I9: 14619 | J9: 24 | K9: 0 | L9: 0 | M9: 0 | R9: =B9/$O$2*100 -> 6.9945037e-05 | S9: =C9/$O$2*100 -> 0 | T9: =D9/$O$2*100 -> 0.0041967022 | U9: =E9/$O$2*100 -> 0 | V9: =F9/$O$2*100 -> 0.00020983511 | W9: =G9/$O$2*100 -> 0.00027978015 | X9: =H9/$O$2*100 -> 0 | Y9: =I9/$O$2*100 -> 1.0225265 | ... AC9: =M9/$O$2*100 -> 0
B10: 35 | C10: 6 | D10: 85 | E10: 0 | F10: 11 | G10: 164 | H10: 0 | I10: 96 | J10: 1410 | K10: 0 | L10: 0 | M10: 0 | R10: =B10/$O$2*100 -> 0.0024480763 | S10: =C10/$O$2*100 -> 0.00041967022 | T10: =D10/$O$2*100 -> 0.0059453282 | U10: =E10/$O$2*100 -> 0 | V10: =F10/$O$2*100 -> 0.00076939541 | W10: =G10/$O$2*100 -> 0.011470986 | X10: =H10/$O$2*100 -> 0 | Y10: =I10/$O$2*100 -> 0.0067147236 | ... AC10: =M10/$O$2*100 -> 0
B11: 308 | C11: 0 | D11: 2305 | E11: 0 | F11: 0 | G11: 34 | H11: 0 | I11: 0 | J11: 0 | K11: 14784 | L11: 0 | M11: 0 | R11: =B11/$O$2*100 -> 0.021543071 | S11: =C11/$O$2*100 -> 0 | T11: =D11/$O$2*100 -> 0.16122331 | U11: =E11/$O$2*100 -> 0 | V11: =F11/$O$2*100 -> 0 | W11: =G11/$O$2*100 -> 0.0023781313 | X11: =H11/$O$2*100 -> 0 | Y11: =I11/$O$2*100 -> 0 | ... AC11: =M11/$O$2*100 -> 0
B12: 812 | C12: 172 | D12: 1407 | E12: 0 | F12: 0 | G12: 2 | H12: 0 | I12: 0 | J12: 0 | K12: 0 | L12: 2361 | M12: 0 | R12: =B12/$O$2*100 -> 0.05679537 | S12: =C12/$O$2*100 -> 0.012030546 | T12: =D12/$O$2*100 -> 0.098412667 | U12: =E12/$O$2*100 -> 0 | V12: =F12/$O$2*100 -> 0 | W12: =G12/$O$2*100 -> 0.00013989007 | X12: =H12/$O$2*100 -> 0 | Y12: =I12/$O$2*100 -> 0 | ... AC12: =M12/$O$2*100 -> 0
B13: 50 | C13: 22 | D13: 16 | E13: 0 | F13: 0 | G13: 15 | H13: 0 | I13: 0 | J13: 0 | K13: 0 | L13: 0 | M13: 0 | R13: =B13/$O$2*100 -> 0.0034972519 | S13: =C13/$O$2*100 -> 0.0015387908 | T13: =D13/$O$2*100 -> 0.0011191206 | U13: =E13/$O$2*100 -> 0 | V13: =F13/$O$2*100 -> 0 | W13: =G13/$O$2*100 -> 0.0010491756 | X13: =H13/$O$2*100 -> 0 | Y13: =I13/$O$2*100 -> 0 | ... AC13: =M13/$O$2*100 -> 0
A18: Predicted | B18: Labeled Sandstone | C18: Labeled Sandstone /Shale | D18: Labeled Shale | E18: Labeled Marls | F18: Labeled Dolomite | G18: Labeled Limestone | H18: Labeled Chalk | I18: Labeled Halite | J18: Labeled Anhydrite | K18: Labeled Tuff | L18: Labeled Coals | M18: Labeled Basement
A19: Sandstone | B19: =IFERROR(B2/SUM(B$2:B$13)*100,0) -> 85.960316 | C19: =IFERROR(C2/SUM(C$2:C$13)*100,0) -> 7.9443259 | D19: =IFERROR(D2/SUM(D$2:D$13)*100,0) -> 1.6263982 | E19: =IFERROR(E2/SUM(E$2:E$13)*100,0) -> 0.83708183 | F19: =IFERROR(F2/SUM(F$2:F$13)*100,0) -> 0 | G19: =IFERROR(G2/SUM(G$2:G$13)*100,0) -> 1.780646 | H19: =IFERROR(H2/SUM(H$2:H$13)*100,0) -> 0.0083703022 | I19: =IFERROR(I2/SUM(I$2:I$13)*100,0) -> 0 | ... M19: =IFERROR(M2/SUM(M$2:M$13)*100,0) -> 0 | R19: =B2*'scoring matrix'!C4 -> 0 | S19: =C2*'scoring matrix'!D4 -> 22420 | T19: =D2*'scoring matrix'!E4 -> 53434.5 | U19: =E2*'scoring matrix'!F4 -> 843 | V19: =F2*'scoring matrix'!G4 -> 0 | W19: =G2*'scoring matrix'!H4 -> 3689 | X19: =H2*'scoring matrix'!I4 -> 3.5 | Y19: =I2*'scoring matrix'!J4 -> 0 | ... AC19: =M2*'scoring matrix'!N4 -> 0
A20: Sandstone /Shale | B20: =IFERROR(B3/SUM(B$2:B$13)*100,0) -> 8.3044134 | C20: =IFERROR(C3/SUM(C$2:C$13)*100,0) -> 80.201549 | D20: =IFERROR(D3/SUM(D$2:D$13)*100,0) -> 5.1648024 | E20: =IFERROR(E3/SUM(E$2:E$13)*100,0) -> 1.3047752 | F20: =IFERROR(F3/SUM(F$2:F$13)*100,0) -> 0 | G20: =IFERROR(G3/SUM(G$2:G$13)*100,0) -> 0.87511826 | H20: =IFERROR(H3/SUM(H$2:H$13)*100,0) -> 0 | I20: =IFERROR(I3/SUM(I$2:I$13)*100,0) -> 0 | ... M20: =IFERROR(M3/SUM(M$2:M$13)*100,0) -> 0 | R20: =B3*'scoring matrix'!C5 -> 34554 | S20: =C3*'scoring matrix'!D5 -> 0 | T20: =D3*'scoring matrix'!E5 -> 115144.75 | U20: =E3*'scoring matrix'!F5 -> 1204.5 | V20: =F3*'scoring matrix'!G5 -> 0 | W20: =G3*'scoring matrix'!H5 -> 1942.5 | X20: =H3*'scoring matrix'!I5 -> 0 | Y20: =I3*'scoring matrix'!J5 -> 0 | ... AC20: =M3*'scoring matrix'!N5 -> 0
A21: Shale | B21: =IFERROR(B4/SUM(B$2:B$13)*100,0) -> 3.0243312 | C21: =IFERROR(C4/SUM(C$2:C$13)*100,0) -> 9.1682199 | D21: =IFERROR(D4/SUM(D$2:D$13)*100,0) -> 90.501332 | E21: =IFERROR(E4/SUM(E$2:E$13)*100,0) -> 9.3955733 | F21: =IFERROR(F4/SUM(F$2:F$13)*100,0) -> 11.538462 | G21: =IFERROR(G4/SUM(G$2:G$13)*100,0) -> 4.1086633 | H21: =IFERROR(H4/SUM(H$2:H$13)*100,0) -> 0.91236294 | I21: =IFERROR(I4/SUM(I$2:I$13)*100,0) -> 0.43972399 | ... M21: =IFERROR(M4/SUM(M$2:M$13)*100,0) -> 0 | R21: =B4*'scoring matrix'!C6 -> 22022 | S21: =C4*'scoring matrix'!D6 -> 30725.375 | T21: =D4*'scoring matrix'!E6 -> 0 | U21: =E4*'scoring matrix'!F6 -> 6308 | V21: =F4*'scoring matrix'!G6 -> 52.5 | W21: =G4*'scoring matrix'!H6 -> 8512 | X21: =H4*'scoring matrix'!I6 -> 408.75 | Y21: =I4*'scoring matrix'!J6 -> 260 | ... AC21: =M4*'scoring matrix'!N6 -> 0
A22: Marl | B22: =IFERROR(B5/SUM(B$2:B$13)*100,0) -> 0.23744749 | C22: =IFERROR(C5/SUM(C$2:C$13)*100,0) -> 0.80293678 | D22: =IFERROR(D5/SUM(D$2:D$13)*100,0) -> 0.87258975 | E22: =IFERROR(E5/SUM(E$2:E$13)*100,0) -> 79.344038 | F22: =IFERROR(F5/SUM(F$2:F$13)*100,0) -> 0 | G22: =IFERROR(G5/SUM(G$2:G$13)*100,0) -> 7.1800243 | H22: =IFERROR(H5/SUM(H$2:H$13)*100,0) -> 2.7203482 | I22: =IFERROR(I5/SUM(I$2:I$13)*100,0) -> 0 | ... M22: =IFERROR(M5/SUM(M$2:M$13)*100,0) -> 0 | R22: =B5*'scoring matrix'!C7 -> 1482 | S22: =C5*'scoring matrix'!D7 -> 3115.75 | T22: =D5*'scoring matrix'!E7 -> 16382 | U22: =E5*'scoring matrix'!F7 -> 0 | V22: =F5*'scoring matrix'!G7 -> 0 | W22: =G5*'scoring matrix'!H7 -> 8500 | X22: =H5*'scoring matrix'!I7 -> 731.25 | Y22: =I5*'scoring matrix'!J7 -> 0 | ... AC22: =M5*'scoring matrix'!N7 -> 0
A23: Dolomite | B23: =IFERROR(B6/SUM(B$2:B$13)*100,0) -> 0.068734799 | C23: =IFERROR(C6/SUM(C$2:C$13)*100,0) -> 0.087167894 | D23: =IFERROR(D6/SUM(D$2:D$13)*100,0) -> 0.16373708 | E23: =IFERROR(E6/SUM(E$2:E$13)*100,0) -> 0.050641961 | F23: =IFERROR(F6/SUM(F$2:F$13)*100,0) -> 76.923077 | G23: =IFERROR(G6/SUM(G$2:G$13)*100,0) -> 0.49499932 | H23: =IFERROR(H6/SUM(H$2:H$13)*100,0) -> 0 | I23: =IFERROR(I6/SUM(I$2:I$13)*100,0) -> 0.013529969 | ... M23: =IFERROR(M6/SUM(M$2:M$13)*100,0) -> 0 | R23: =B6*'scoring matrix'!C8 -> 536.25 | S23: =C6*'scoring matrix'!D8 -> 492 | T23: =D6*'scoring matrix'!E8 -> 5379.5 | U23: =E6*'scoring matrix'!F8 -> 42.5 | V23: =F6*'scoring matrix'!G8 -> 0 | W23: =G6*'scoring matrix'!H8 -> 769.125 | X23: =H6*'scoring matrix'!I8 -> 0 | Y23: =I6*'scoring matrix'!J8 -> 7.5 | ... AC23: =M6*'scoring matrix'!N8 -> 0
A24: Limestone | B24: =IFERROR(B7/SUM(B$2:B$13)*100,0) -> 1.7832595 | C24: =IFERROR(C7/SUM(C$2:C$13)*100,0) -> 1.6540639 | D24: =IFERROR(D7/SUM(D$2:D$13)*100,0) -> 1.2579099 | E24: =IFERROR(E7/SUM(E$2:E$13)*100,0) -> 8.8891537 | F24: =IFERROR(F7/SUM(F$2:F$13)*100,0) -> 0.76923077 | G24: =IFERROR(G7/SUM(G$2:G$13)*100,0) -> 79.723611 | H24: =IFERROR(H7/SUM(H$2:H$13)*100,0) -> 7.1817193 | I24: =IFERROR(I7/SUM(I$2:I$13)*100,0) -> 0 | ... M24: =IFERROR(M7/SUM(M$2:M$13)*100,0) -> 0 | R24: =B7*'scoring matrix'!C9 -> 12985 | S24: =C7*'scoring matrix'!D9 -> 8752.5 | T24: =D7*'scoring matrix'!E9 -> 41328 | U24: =E7*'scoring matrix'!F9 -> 5968 | V24: =F7*'scoring matrix'!G9 -> 2.625 | W24: =G7*'scoring matrix'!H9 -> 0 | X24: =H7*'scoring matrix'!I9 -> 1179.75 | Y24: =I7*'scoring matrix'!J9 -> 0 | ... AC24: =M7*'scoring matrix'!N9 -> 0
A25: Chalk | B25: =IFERROR(B8/SUM(B$2:B$13)*100,0) -> 0.041817675 | C25: =IFERROR(C8/SUM(C$2:C$13)*100,0) -> 0 | D25: =IFERROR(D8/SUM(D$2:D$13)*100,0) -> 0.00063918185 | E25: =IFERROR(E8/SUM(E$2:E$13)*100,0) -> 0.17873633 | F25: =IFERROR(F8/SUM(F$2:F$13)*100,0) -> 0 | G25: =IFERROR(G8/SUM(G$2:G$13)*100,0) -> 5.466955 | H25: =IFERROR(H8/SUM(H$2:H$13)*100,0) -> 89.177199 | I25: =IFERROR(I8/SUM(I$2:I$13)*100,0) -> 0 | ... M25: =IFERROR(M8/SUM(M$2:M$13)*100,0) -> 0 | R25: =B8*'scoring matrix'!C10 -> 304.5 | S25: =C8*'scoring matrix'!D10 -> 0 | T25: =D8*'scoring matrix'!E10 -> 22.5 | U25: =E8*'scoring matrix'!F10 -> 135 | V25: =F8*'scoring matrix'!G10 -> 0 | W25: =G8*'scoring matrix'!H10 -> 4449.5 | X25: =H8*'scoring matrix'!I10 -> 0 | Y25: =I8*'scoring matrix'!J10 -> 0 | ... AC25: =M8*'scoring matrix'!N10 -> 0 | AE25: =SUM(R19:AC30) -> 442690.62
A26: Halite | B26: =IFERROR(B9/SUM(B$2:B$13)*100,0) -> 0.00048066293 | C26: =IFERROR(C9/SUM(C$2:C$13)*100,0) -> 0 | D26: =IFERROR(D9/SUM(D$2:D$13)*100,0) -> 0.0063918185 | E26: =IFERROR(E9/SUM(E$2:E$13)*100,0) -> 0 | F26: =IFERROR(F9/SUM(F$2:F$13)*100,0) -> 2.3076923 | G26: =IFERROR(G9/SUM(G$2:G$13)*100,0) -> 0.00675767 | H26: =IFERROR(H9/SUM(H$2:H$13)*100,0) -> 0 | I26: =IFERROR(I9/SUM(I$2:I$13)*100,0) -> 98.897308 | ... M26: =IFERROR(M9/SUM(M$2:M$13)*100,0) -> 0 | R26: =B9*'scoring matrix'!C11 -> 4 | S26: =C9*'scoring matrix'!D11 -> 0 | T26: =D9*'scoring matrix'!E11 -> 240 | U26: =E9*'scoring matrix'!F11 -> 0 | V26: =F9*'scoring matrix'!G11 -> 11.25 | W26: =G9*'scoring matrix'!H11 -> 16 | X26: =H9*'scoring matrix'!I11 -> 0 | Y26: =I9*'scoring matrix'!J11 -> 0 | ... AC26: =M9*'scoring matrix'!N11 -> 0
A27: Anhydrite | B27: =IFERROR(B10/SUM(B$2:B$13)*100,0) -> 0.016823203 | C27: =IFERROR(C10/SUM(C$2:C$13)*100,0) -> 0.0042520924 | D27: =IFERROR(D10/SUM(D$2:D$13)*100,0) -> 0.0090550762 | E27: =IFERROR(E10/SUM(E$2:E$13)*100,0) -> 0 | F27: =IFERROR(F10/SUM(F$2:F$13)*100,0) -> 8.4615385 | G27: =IFERROR(G10/SUM(G$2:G$13)*100,0) -> 0.27706447 | H27: =IFERROR(H10/SUM(H$2:H$13)*100,0) -> 0 | I27: =IFERROR(I10/SUM(I$2:I$13)*100,0) -> 0.64943851 | ... M27: =IFERROR(M10/SUM(M$2:M$13)*100,0) -> 0 | R27: =B10*'scoring matrix'!C12 -> 140 | S27: =C10*'scoring matrix'!D12 -> 24 | T27: =D10*'scoring matrix'!E12 -> 340 | U27: =E10*'scoring matrix'!F12 -> 0 | V27: =F10*'scoring matrix'!G12 -> 35.75 | W27: =G10*'scoring matrix'!H12 -> 615 | X27: =H10*'scoring matrix'!I12 -> 0 | Y27: =I10*'scoring matrix'!J12 -> 264 | ... AC27: =M10*'scoring matrix'!N12 -> 0
A28: Tuff | B28: =IFERROR(B11/SUM(B$2:B$13)*100,0) -> 0.14804418 | C28: =IFERROR(C11/SUM(C$2:C$13)*100,0) -> 0 | D28: =IFERROR(D11/SUM(D$2:D$13)*100,0) -> 0.24555236 | E28: =IFERROR(E11/SUM(E$2:E$13)*100,0) -> 0 | F28: =IFERROR(F11/SUM(F$2:F$13)*100,0) -> 0 | G28: =IFERROR(G11/SUM(G$2:G$13)*100,0) -> 0.057440195 | H28: =IFERROR(H11/SUM(H$2:H$13)*100,0) -> 0 | I28: =IFERROR(I11/SUM(I$2:I$13)*100,0) -> 0 | ... M28: =IFERROR(M11/SUM(M$2:M$13)*100,0) -> 0 | R28: =B11*'scoring matrix'!C13 -> 770 | S28: =C11*'scoring matrix'!D13 -> 0 | T28: =D11*'scoring matrix'!E13 -> 6338.75 | U28: =E11*'scoring matrix'!F13 -> 0 | V28: =F11*'scoring matrix'!G13 -> 0 | W28: =G11*'scoring matrix'!H13 -> 119 | X28: =H11*'scoring matrix'!I13 -> 0 | Y28: =I11*'scoring matrix'!J13 -> 0 | ... AC28: =M11*'scoring matrix'!N13 -> 0
A29: Coals | B29: =IFERROR(B12/SUM(B$2:B$13)*100,0) -> 0.3902983 | C29: =IFERROR(C12/SUM(C$2:C$13)*100,0) -> 0.12189332 | D29: =IFERROR(D12/SUM(D$2:D$13)*100,0) -> 0.14988814 | E29: =IFERROR(E12/SUM(E$2:E$13)*100,0) -> 0 | F29: =IFERROR(F12/SUM(F$2:F$13)*100,0) -> 0 | G29: =IFERROR(G12/SUM(G$2:G$13)*100,0) -> 0.003378835 | H29: =IFERROR(H12/SUM(H$2:H$13)*100,0) -> 0 | I29: =IFERROR(I12/SUM(I$2:I$13)*100,0) -> 0 | ... M29: =IFERROR(M12/SUM(M$2:M$13)*100,0) -> 0 | R29: =B12*'scoring matrix'!C14 -> 3146.5 | S29: =C12*'scoring matrix'!D14 -> 645 | T29: =D12*'scoring matrix'!E14 -> 4572.75 | U29: =E12*'scoring matrix'!F14 -> 0 | V29: =F12*'scoring matrix'!G14 -> 0 | W29: =G12*'scoring matrix'!H14 -> 8 | X29: =H12*'scoring matrix'!I14 -> 0 | Y29: =I12*'scoring matrix'!J14 -> 0 | ... AC29: =M12*'scoring matrix'!N14 -> 0
A30: Basement | B30: =IFERROR(B13/SUM(B$2:B$13)*100,0) -> 0.024033147 | C30: =IFERROR(C13/SUM(C$2:C$13)*100,0) -> 0.015591005 | D30: =IFERROR(D13/SUM(D$2:D$13)*100,0) -> 0.0017044849 | E30: =IFERROR(E13/SUM(E$2:E$13)*100,0) -> 0 | F30: =IFERROR(F13/SUM(F$2:F$13)*100,0) -> 0 | G30: =IFERROR(G13/SUM(G$2:G$13)*100,0) -> 0.025341262 | H30: =IFERROR(H13/SUM(H$2:H$13)*100,0) -> 0 | I30: =IFERROR(I13/SUM(I$2:I$13)*100,0) -> 0 | ... M30: =IFERROR(M13/SUM(M$2:M$13)*100,0) -> 0 | R30: =B13*'scoring matrix'!C15 -> 162.5 | S30: =C13*'scoring matrix'!D15 -> 66 | T30: =D13*'scoring matrix'!E15 -> 48 | U30: =E13*'scoring matrix'!F15 -> 0 | V30: =F13*'scoring matrix'!G15 -> 0 | W30: =G13*'scoring matrix'!H15 -> 54.375 | X30: =H13*'scoring matrix'!I15 -> 0 | Y30: =I13*'scoring matrix'!J15 -> 0 | ... AC30: =M13*'scoring matrix'!N15 -> 0

Sheet Comparison
AE6: Differential score olawale GIR
B7: 1st Olawale Predicted | C7: Labeled Sandstone | D7: Labeled Sandstone /Shale | E7: Labeled Shale | F7: Labeled Marls | G7: Labeled Dolomite | H7: Labeled Limestone | I7: Labeled Chalk | J7: Labeled Halite | K7: Labeled Anhydrite | L7: Labeled Tuff | M7: Labeled Coals | N7: Labeled Basement | P7: 2ndGIR Predicted | Q7: Labeled Sandstone | R7: Labeled Sandstone /Shale | S7: Labeled Shale | T7: Labeled Marls | U7: Labeled Dolomite | V7: Labeled Limestone | W7: Labeled Chalk | X7: Labeled Halite | Y7: Labeled Anhydrite | Z7: Labeled Tuff | AA7: Labeled Coals | AB7: Labeled Basement | AD7: Olwale /GIR comparison | AE7: Labeled Sandstone | AF7: Labeled Sandstone /Shale | AG7: Labeled Shale | AH7: Labeled Marls | AI7: Labeled Dolomite | AJ7: Labeled Limestone | AK7: Labeled Chalk | AL7: Labeled Halite | AM7: Labeled Anhydrite | AN7: Labeled Tuff | AO7: Labeled Coals | AP7: Labeled Basement
B8: Sandstone | C8: =Olawale_conf!B19 -> 78.512745 | D8: =Olawale_conf!C19 -> 20.49309 | E8: =Olawale_conf!D19 -> 1.4039855 | F8: =Olawale_conf!E19 -> 5.5120167 | G8: =Olawale_conf!F19 -> 0 | H8: =Olawale_conf!G19 -> 2.6565899 | I8: =Olawale_conf!H19 -> 0 | J8: =Olawale_conf!I19 -> 0 | ... N8: =Olawale_conf!M19 -> 0 | P8: Sandstone | Q8: ='GIR_conf '!B19 -> 74.981615 | R8: ='GIR_conf '!C19 -> 24.483957 | S8: ='GIR_conf '!D19 -> 1.535274 | T8: ='GIR_conf '!E19 -> 0.60750132 | U8: ='GIR_conf '!F19 -> 0 | V8: ='GIR_conf '!G19 -> 2.8056351 | W8: ='GIR_conf '!H19 -> 0 | X8: ='GIR_conf '!I19 -> 0 | ... AB8: ='GIR_conf '!M19 -> 0 | AD8: Sandstone | AE8: =Olawale_conf!B2*'scoring matrix'!C4-'GIR_conf '!B2*'scoring matrix'!C4 -> 0 | AF8: =Olawale_conf!C2*'scoring matrix'!D4-'GIR_conf '!C2*'scoring matrix'!D4 -> -2182 | AG8: =Olawale_conf!D2*'scoring matrix'!E4-'GIR_conf '!D2*'scoring matrix'!E4 -> -269.5 | AH8: =Olawale_conf!E2*'scoring matrix'!F4-'GIR_conf '!E2*'scoring matrix'!F4 -> 564 | AI8: =Olawale_conf!F2*'scoring matrix'!G4-'GIR_conf '!F2*'scoring matrix'!G4 -> 0 | AJ8: =Olawale_conf!G2*'scoring matrix'!H4-'GIR_conf '!G2*'scoring matrix'!H4 -> -10.5 | AK8: =Olawale_conf!H2*'scoring matrix'!I4-'GIR_conf '!H2*'scoring matrix'!I4 -> 0 | AL8: =Olawale_conf!I2*'scoring matrix'!J4-'GIR_conf '!I2*'scoring matrix'!J4 -> 0 | ... AP8: =Olawale_conf!M2*'scoring matrix'!N4-'GIR_conf '!M2*'scoring matrix'!N4 -> 0
B9: Sandstone /Shale | C9: =Olawale_conf!B20 -> 12.73787 | D9: =Olawale_conf!C20 -> 55.464824 | E9: =Olawale_conf!D20 -> 8.301882 | F9: =Olawale_conf!E20 -> 4.4409613 | G9: =Olawale_conf!F20 -> 0 | H9: =Olawale_conf!G20 -> 0.28627047 | I9: =Olawale_conf!H20 -> 0 | J9: =Olawale_conf!I20 -> 0 | ... N9: =Olawale_conf!M20 -> 0 | P9: Sandstone /Shale | Q9: ='GIR_conf '!B20 -> 12.840124 | R9: ='GIR_conf '!C20 -> 51.788269 | S9: ='GIR_conf '!D20 -> 6.6185365 | T9: ='GIR_conf '!E20 -> 6.6032752 | U9: ='GIR_conf '!F20 -> 0 | V9: ='GIR_conf '!G20 -> 0.26265521 | W9: ='GIR_conf '!H20 -> 0 | X9: ='GIR_conf '!I20 -> 0 | ... AB9: ='GIR_conf '!M20 -> 0 | AD9: Sandstone /Shale | AE9: =Olawale_conf!B3*'scoring matrix'!C5-'GIR_conf '!B3*'scoring matrix'!C5 -> 136 | AF9: =Olawale_conf!C3*'scoring matrix'!D5-'GIR_conf '!C3*'scoring matrix'!D5 -> 0 | AG9: =Olawale_conf!D3*'scoring matrix'!E5-'GIR_conf '!D3*'scoring matrix'!E5 -> 3458 | AH9: =Olawale_conf!E3*'scoring matrix'!F5-'GIR_conf '!E3*'scoring matrix'!F5 -> -220 | AI9: =Olawale_conf!F3*'scoring matrix'!G5-'GIR_conf '!F3*'scoring matrix'!G5 -> 0 | AJ9: =Olawale_conf!G3*'scoring matrix'!H5-'GIR_conf '!G3*'scoring matrix'!H5 -> 11.25 | AK9: =Olawale_conf!H3*'scoring matrix'!I5-'GIR_conf '!H3*'scoring matrix'!I5 -> 0 | AL9: =Olawale_conf!I3*'scoring matrix'!J5-'GIR_conf '!I3*'scoring matrix'!J5 -> 0 | ... AP9: =Olawale_conf!M3*'scoring matrix'!N5-'GIR_conf '!M3*'scoring matrix'!N5 -> 0
B10: Shale | C10: =Olawale_conf!B21 -> 3.6233411 | D10: =Olawale_conf!C21 -> 14.133166 | E10: =Olawale_conf!D21 -> 86.307367 | F10: =Olawale_conf!E21 -> 32.941484 | G10: =Olawale_conf!F21 -> 0 | H10: =Olawale_conf!G21 -> 2.6909424 | I10: =Olawale_conf!H21 -> 2.3584906 | J10: =Olawale_conf!I21 -> 0.21426385 | ... N10: =Olawale_conf!M21 -> 0 | P10: Shale | Q10: ='GIR_conf '!B21 -> 4.9566113 | R10: ='GIR_conf '!C21 -> 21.43879 | S10: ='GIR_conf '!D21 -> 87.109104 | T10: ='GIR_conf '!E21 -> 21.658743 | U10: ='GIR_conf '!F21 -> 8.4158416 | V10: ='GIR_conf '!G21 -> 2.7698185 | W10: ='GIR_conf '!H21 -> 2.5700935 | X10: ='GIR_conf '!I21 -> 0.031560675 | ... AB10: ='GIR_conf '!M21 -> 0 | AD10: Shale | AE10: =Olawale_conf!B4*'scoring matrix'!C6-'GIR_conf '!B4*'scoring matrix'!C6 -> -553 | AF10: =Olawale_conf!C4*'scoring matrix'!D6-'GIR_conf '!C4*'scoring matrix'!D6 -> -2845.25 | AG10: =Olawale_conf!D4*'scoring matrix'!E6-'GIR_conf '!D4*'scoring matrix'!E6 -> 0 | AH10: =Olawale_conf!E4*'scoring matrix'!F6-'GIR_conf '!E4*'scoring matrix'!F6 -> 882 | AI10: =Olawale_conf!F4*'scoring matrix'!G6-'GIR_conf '!F4*'scoring matrix'!G6 -> -59.5 | AJ10: =Olawale_conf!G4*'scoring matrix'!H6-'GIR_conf '!G4*'scoring matrix'!H6 -> 10.5 | AK10: =Olawale_conf!H4*'scoring matrix'!I6-'GIR_conf '!H4*'scoring matrix'!I6 -> -11.25 | AL10: =Olawale_conf!I4*'scoring matrix'!J6-'GIR_conf '!I4*'scoring matrix'!J6 -> 48 | ... AP10: =Olawale_conf!M4*'scoring matrix'!N6-'GIR_conf '!M4*'scoring matrix'!N6 -> 0 | AR10: =SUM(AE8:AP19) -> -1158.5
B11: Marl | C11: =Olawale_conf!B22 -> 0.11937364 | D11: =Olawale_conf!C22 -> 7.6947236 | E11: =Olawale_conf!D22 -> 2.0493659 | F11: =Olawale_conf!E22 -> 30.69488 | G11: =Olawale_conf!F22 -> 0 | H11: =Olawale_conf!G22 -> 11.679835 | I11: =Olawale_conf!H22 -> 5.1100629 | J11: =Olawale_conf!I22 -> 0 | ... N11: =Olawale_conf!M22 -> 0 | P11: Marl | Q11: ='GIR_conf '!B22 -> 0.13237241 | R11: ='GIR_conf '!C22 -> 1.5532393 | S11: ='GIR_conf '!D22 -> 2.2314879 | T11: ='GIR_conf '!E22 -> 42.41944 | U11: ='GIR_conf '!F22 -> 0.99009901 | V11: ='GIR_conf '!G22 -> 9.5152818 | W11: ='GIR_conf '!H22 -> 6.3862928 | X11: ='GIR_conf '!I22 -> 0 | ... AB11: ='GIR_conf '!M22 -> 0 | AD11: Marl | AE11: =Olawale_conf!B5*'scoring matrix'!C7-'GIR_conf '!B5*'scoring matrix'!C7 -> -3 | AF11: =Olawale_conf!C5*'scoring matrix'!D7-'GIR_conf '!C5*'scoring matrix'!D7 -> 929.5 | AG11: =Olawale_conf!D5*'scoring matrix'!E7-'GIR_conf '!D5*'scoring matrix'!E7 -> -210 | AH11: =Olawale_conf!E5*'scoring matrix'!F7-'GIR_conf '!E5*'scoring matrix'!F7 -> 0 | AI11: =Olawale_conf!F5*'scoring matrix'!G7-'GIR_conf '!F5*'scoring matrix'!G7 -> -5 | AJ11: =Olawale_conf!G5*'scoring matrix'!H7-'GIR_conf '!G5*'scoring matrix'!H7 -> 446 | AK11: =Olawale_conf!H5*'scoring matrix'!I7-'GIR_conf '!H5*'scoring matrix'!I7 -> -38.25 | AL11: =Olawale_conf!I5*'scoring matrix'!J7-'GIR_conf '!I5*'scoring matrix'!J7 -> 0 | ... AP11: =Olawale_conf!M5*'scoring matrix'!N7-'GIR_conf '!M5*'scoring matrix'!N7 -> 0
B12: Dolomite | C12: =Olawale_conf!B23 -> 0.035109894 | D12: =Olawale_conf!C23 -> 0 | E12: =Olawale_conf!D23 -> 0.19248188 | F12: =Olawale_conf!E23 -> 0.026123302 | G12: =Olawale_conf!F23 -> 5.5555556 | H12: =Olawale_conf!G23 -> 0.10305737 | I12: =Olawale_conf!H23 -> 0 | J12: =Olawale_conf!I23 -> 0.030609122 | ... N12: =Olawale_conf!M23 -> 0 | P12: Dolomite | Q12: ='GIR_conf '!B23 -> 0.029416091 | R12: ='GIR_conf '!C23 -> 0 | S12: ='GIR_conf '!D23 -> 0.2020436 | T12: ='GIR_conf '!E23 -> 0.1056524 | U12: ='GIR_conf '!F23 -> 40.594059 | V12: ='GIR_conf '!G23 -> 0.14326648 | W12: ='GIR_conf '!H23 -> 0 | X12: ='GIR_conf '!I23 -> 0 | ... AB12: ='GIR_conf '!M23 -> 0 | AD12: Dolomite | AE12: =Olawale_conf!B6*'scoring matrix'!C8-'GIR_conf '!B6*'scoring matrix'!C8 -> 3.75 | AF12: =Olawale_conf!C6*'scoring matrix'!D8-'GIR_conf '!C6*'scoring matrix'!D8 -> 0 | AG12: =Olawale_conf!D6*'scoring matrix'!E8-'GIR_conf '!D6*'scoring matrix'!E8 -> -14 | AH12: =Olawale_conf!E6*'scoring matrix'!F8-'GIR_conf '!E6*'scoring matrix'!F8 -> -7.5 | AI12: =Olawale_conf!F6*'scoring matrix'!G8-'GIR_conf '!F6*'scoring matrix'!G8 -> 0 | AJ12: =Olawale_conf!G6*'scoring matrix'!H8-'GIR_conf '!G6*'scoring matrix'!H8 -> -7.875 | AK12: =Olawale_conf!H6*'scoring matrix'!I8-'GIR_conf '!H6*'scoring matrix'!I8 -> 0 | AL12: =Olawale_conf!I6*'scoring matrix'!J8-'GIR_conf '!I6*'scoring matrix'!J8 -> 7.5 | ... AP12: =Olawale_conf!M6*'scoring matrix'!N8-'GIR_conf '!M6*'scoring matrix'!N8 -> 0
B13: Limestone | C13: =Olawale_conf!B24 -> 4.0797697 | D13: =Olawale_conf!C24 -> 1.9158291 | E13: =Olawale_conf!D24 -> 1.366244 | F13: =Olawale_conf!E24 -> 26.227795 | G13: =Olawale_conf!F24 -> 11.111111 | H13: =Olawale_conf!G24 -> 60.861102 | I13: =Olawale_conf!H24 -> 15.644654 | J13: =Olawale_conf!I24 -> 0 | ... N13: =Olawale_conf!M24 -> 0 | P13: Limestone | Q13: ='GIR_conf '!B24 -> 5.5375791 | R13: ='GIR_conf '!C24 -> 0.52115267 | S13: ='GIR_conf '!D24 -> 1.3666898 | T13: ='GIR_conf '!E24 -> 27.311146 | U13: ='GIR_conf '!F24 -> 6.4356436 | V13: ='GIR_conf '!G24 -> 64.19532 | W13: ='GIR_conf '!H24 -> 1.2461059 | X13: ='GIR_conf '!I24 -> 0 | ... AB13: ='GIR_conf '!M24 -> 0 | AD13: Limestone | AE13: =Olawale_conf!B7*'scoring matrix'!C9-'GIR_conf '!B7*'scoring matrix'!C9 -> -602 | AF13: =Olawale_conf!C7*'scoring matrix'!D9-'GIR_conf '!C7*'scoring matrix'!D9 -> 266.25 | AG13: =Olawale_conf!D7*'scoring matrix'!E9-'GIR_conf '!D7*'scoring matrix'!E9 -> 84 | AH13: =Olawale_conf!E7*'scoring matrix'!F9-'GIR_conf '!E7*'scoring matrix'!F9 -> -60 | AI13: =Olawale_conf!F7*'scoring matrix'!G9-'GIR_conf '!F7*'scoring matrix'!G9 -> -28.875 | AJ13: =Olawale_conf!G7*'scoring matrix'!H9-'GIR_conf '!G7*'scoring matrix'!H9 -> 0 | AK13: =Olawale_conf!H7*'scoring matrix'!I9-'GIR_conf '!H7*'scoring matrix'!I9 -> 251.625 | AL13: =Olawale_conf!I7*'scoring matrix'!J9-'GIR_conf '!I7*'scoring matrix'!J9 -> 0 | ... AP13: =Olawale_conf!M7*'scoring matrix'!N9-'GIR_conf '!M7*'scoring matrix'!N9 -> 0
B14: Chalk | C14: =Olawale_conf!B25 -> 0.54069237 | D14: =Olawale_conf!C25 -> 0 | E14: =Olawale_conf!D25 -> 0.0012580515 | F14: =Olawale_conf!E25 -> 0.15673981 | G14: =Olawale_conf!F25 -> 0 | H14: =Olawale_conf!G25 -> 21.103859 | I14: =Olawale_conf!H25 -> 76.886792 | J14: =Olawale_conf!I25 -> 0 | ... N14: =Olawale_conf!M25 -> 0 | P14: Chalk | Q14: ='GIR_conf '!B25 -> 0.36770113 | R14: ='GIR_conf '!C25 -> 0 | S14: ='GIR_conf '!D25 -> 0 | T14: ='GIR_conf '!E25 -> 1.2942419 | U14: ='GIR_conf '!F25 -> 0 | V14: ='GIR_conf '!G25 -> 19.734957 | W14: ='GIR_conf '!H25 -> 89.797508 | X14: ='GIR_conf '!I25 -> 0 | ... AB14: ='GIR_conf '!M25 -> 0 | AD14: Chalk | AE14: =Olawale_conf!B8*'scoring matrix'!C10-'GIR_conf '!B8*'scoring matrix'!C10 -> 94.5 | AF14: =Olawale_conf!C8*'scoring matrix'!D10-'GIR_conf '!C8*'scoring matrix'!D10 -> 0 | AG14: =Olawale_conf!D8*'scoring matrix'!E10-'GIR_conf '!D8*'scoring matrix'!E10 -> 3.75 | AH14: =Olawale_conf!E8*'scoring matrix'!F10-'GIR_conf '!E8*'scoring matrix'!F10 -> -96.75 | AI14: =Olawale_conf!F8*'scoring matrix'!G10-'GIR_conf '!F8*'scoring matrix'!G10 -> 0 | AJ14: =Olawale_conf!G8*'scoring matrix'!H10-'GIR_conf '!G8*'scoring matrix'!H10 -> 261.25 | AK14: =Olawale_conf!H8*'scoring matrix'!I10-'GIR_conf '!H8*'scoring matrix'!I10 -> 0 | AL14: =Olawale_conf!I8*'scoring matrix'!J10-'GIR_conf '!I8*'scoring matrix'!J10 -> 0 | ... AP14: =Olawale_conf!M8*'scoring matrix'!N10-'GIR_conf '!M8*'scoring matrix'!N10 -> 0
B15: Halite | C15: =Olawale_conf!B26 -> 0 | D15: =Olawale_conf!C26 -> 0 | E15: =Olawale_conf!D26 -> 0.026419082 | F15: =Olawale_conf!E26 -> 0 | G15: =Olawale_conf!F26 -> 27.777778 | H15: =Olawale_conf!G26 -> 0.080155731 | I15: =Olawale_conf!H26 -> 0 | J15: =Olawale_conf!I26 -> 98.852158 | ... N15: =Olawale_conf!M26 -> 0 | P15: Halite | Q15: ='GIR_conf '!B26 -> 0.058832181 | R15: ='GIR_conf '!C26 -> 0 | S15: ='GIR_conf '!D26 -> 0.25738038 | T15: ='GIR_conf '!E26 -> 0 | U15: ='GIR_conf '!F26 -> 13.366337 | V15: ='GIR_conf '!G26 -> 0.023877746 | W15: ='GIR_conf '!H26 -> 0 | X15: ='GIR_conf '!I26 -> 98.784914 | ... AB15: ='GIR_conf '!M26 -> 0 | AD15: Halite | AE15: =Olawale_conf!B9*'scoring matrix'!C11-'GIR_conf '!B9*'scoring matrix'!C11 -> -32 | AF15: =Olawale_conf!C9*'scoring matrix'!D11-'GIR_conf '!C9*'scoring matrix'!D11 -> 0 | AG15: =Olawale_conf!D9*'scoring matrix'!E11-'GIR_conf '!D9*'scoring matrix'!E11 -> -716 | AH15: =Olawale_conf!E9*'scoring matrix'!F11-'GIR_conf '!E9*'scoring matrix'!F11 -> 0 | AI15: =Olawale_conf!F9*'scoring matrix'!G11-'GIR_conf '!F9*'scoring matrix'!G11 -> -82.5 | AJ15: =Olawale_conf!G9*'scoring matrix'!H11-'GIR_conf '!G9*'scoring matrix'!H11 -> 20 | AK15: =Olawale_conf!H9*'scoring matrix'!I11-'GIR_conf '!H9*'scoring matrix'!I11 -> 0 | AL15: =Olawale_conf!I9*'scoring matrix'!J11-'GIR_conf '!I9*'scoring matrix'!J11 -> 0 | ... AP15: =Olawale_conf!M9*'scoring matrix'!N11-'GIR_conf '!M9*'scoring matrix'!N11 -> 0
B16: Anhydrite | C16: =Olawale_conf!B27 -> 0.12639562 | D16: =Olawale_conf!C27 -> 0 | E16: =Olawale_conf!D27 -> 0.0088063607 | F16: =Olawale_conf!E27 -> 0 | G16: =Olawale_conf!F27 -> 55.555556 | H16: =Olawale_conf!G27 -> 0.41222947 | I16: =Olawale_conf!H27 -> 0 | J16: =Olawale_conf!I27 -> 0.90296908 | ... N16: =Olawale_conf!M27 -> 0 | P16: Anhydrite | Q16: ='GIR_conf '!B27 -> 0.14708045 | R16: ='GIR_conf '!C27 -> 0.030656039 | S16: ='GIR_conf '!D27 -> 0.0090083134 | T16: ='GIR_conf '!E27 -> 0 | U16: ='GIR_conf '!F27 -> 30.19802 | V16: ='GIR_conf '!G27 -> 0.4417383 | W16: ='GIR_conf '!H27 -> 0 | X16: ='GIR_conf '!I27 -> 1.1835253 | ... AB16: ='GIR_conf '!M27 -> 0 | AD16: Anhydrite | AE16: =Olawale_conf!B10*'scoring matrix'!C12-'GIR_conf '!B10*'scoring matrix'!C12 -> -8 | AF16: =Olawale_conf!C10*'scoring matrix'!D12-'GIR_conf '!C10*'scoring matrix'!D12 -> -12 | AG16: =Olawale_conf!D10*'scoring matrix'!E12-'GIR_conf '!D10*'scoring matrix'!E12 -> 0 | AH16: =Olawale_conf!E10*'scoring matrix'!F12-'GIR_conf '!E10*'scoring matrix'!F12 -> 0 | AI16: =Olawale_conf!F10*'scoring matrix'!G12-'GIR_conf '!F10*'scoring matrix'!G12 -> -165.75 | AJ16: =Olawale_conf!G10*'scoring matrix'!H12-'GIR_conf '!G10*'scoring matrix'!H12 -> -3.75 | AK16: =Olawale_conf!H10*'scoring matrix'!I12-'GIR_conf '!H10*'scoring matrix'!I12 -> 0 | AL16: =Olawale_conf!I10*'scoring matrix'!J12-'GIR_conf '!I10*'scoring matrix'!J12 -> -44 | ... AP16: =Olawale_conf!M10*'scoring matrix'!N12-'GIR_conf '!M10*'scoring matrix'!N12 -> 0
B17: Tuff | C17: =Olawale_conf!B28 -> 0.0070219788 | D17: =Olawale_conf!C28 -> 0 | E17: =Olawale_conf!D28 -> 0.27677134 | F17: =Olawale_conf!E28 -> 0 | G17: =Olawale_conf!F28 -> 0 | H17: =Olawale_conf!G28 -> 0.10305737 | I17: =Olawale_conf!H28 -> 0 | J17: =Olawale_conf!I28 -> 0 | ... N17: =Olawale_conf!M28 -> 0 | P17: Tuff | Q17: ='GIR_conf '!B28 -> 0.85306663 | R17: ='GIR_conf '!C28 -> 0.020437359 | S17: ='GIR_conf '!D28 -> 0.62672123 | T17: ='GIR_conf '!E28 -> 0 | U17: ='GIR_conf '!F28 -> 0 | V17: ='GIR_conf '!G28 -> 0.10744986 | W17: ='GIR_conf '!H28 -> 0 | X17: ='GIR_conf '!I28 -> 0 | ... AB17: ='GIR_conf '!M28 -> 0 | AD17: Tuff | AE17: =Olawale_conf!B11*'scoring matrix'!C13-'GIR_conf '!B11*'scoring matrix'!C13 -> -287.5 | AF17: =Olawale_conf!C11*'scoring matrix'!D13-'GIR_conf '!C11*'scoring matrix'!D13 -> -6 | AG17: =Olawale_conf!D11*'scoring matrix'!E13-'GIR_conf '!D11*'scoring matrix'!E13 -> -734.25 | AH17: =Olawale_conf!E11*'scoring matrix'!F13-'GIR_conf '!E11*'scoring matrix'!F13 -> 0 | AI17: =Olawale_conf!F11*'scoring matrix'!G13-'GIR_conf '!F11*'scoring matrix'!G13 -> 0 | AJ17: =Olawale_conf!G11*'scoring matrix'!H13-'GIR_conf '!G11*'scoring matrix'!H13 -> 0 | AK17: =Olawale_conf!H11*'scoring matrix'!I13-'GIR_conf '!H11*'scoring matrix'!I13 -> 0 | AL17: =Olawale_conf!I11*'scoring matrix'!J13-'GIR_conf '!I11*'scoring matrix'!J13 -> 0 | ... AP17: =Olawale_conf!M11*'scoring matrix'!N13-'GIR_conf '!M11*'scoring matrix'!N13 -> 0
B18: Coals | C18: =Olawale_conf!B29 -> 0.21768134 | D18: =Olawale_conf!C29 -> 0.29836683 | E18: =Olawale_conf!D29 -> 0.06541868 | F18: =Olawale_conf!E29 -> 0 | G18: =Olawale_conf!F29 -> 0 | H18: =Olawale_conf!G29 -> 0.022901637 | I18: =Olawale_conf!H29 -> 0 | J18: =Olawale_conf!I29 -> 0 | ... N18: =Olawale_conf!M29 -> 0 | P18: Coals | Q18: ='GIR_conf '!B29 -> 0.095602294 | R18: ='GIR_conf '!C29 -> 0.16349888 | S18: ='GIR_conf '!D29 -> 0.043754665 | T18: ='GIR_conf '!E29 -> 0 | U18: ='GIR_conf '!F29 -> 0 | V18: ='GIR_conf '!G29 -> 0 | W18: ='GIR_conf '!H29 -> 0 | X18: ='GIR_conf '!I29 -> 0 | ... AB18: ='GIR_conf '!M29 -> 0 | AD18: Coals | AE18: =Olawale_conf!B12*'scoring matrix'!C14-'GIR_conf '!B12*'scoring matrix'!C14 -> 69.75 | AF18: =Olawale_conf!C12*'scoring matrix'!D14-'GIR_conf '!C12*'scoring matrix'!D14 -> 11.25 | AG18: =Olawale_conf!D12*'scoring matrix'!E14-'GIR_conf '!D12*'scoring matrix'!E14 -> 58.5 | AH18: =Olawale_conf!E12*'scoring matrix'!F14-'GIR_conf '!E12*'scoring matrix'!F14 -> 0 | AI18: =Olawale_conf!F12*'scoring matrix'!G14-'GIR_conf '!F12*'scoring matrix'!G14 -> 0 | AJ18: =Olawale_conf!G12*'scoring matrix'!H14-'GIR_conf '!G12*'scoring matrix'!H14 -> 8 | AK18: =Olawale_conf!H12*'scoring matrix'!I14-'GIR_conf '!H12*'scoring matrix'!I14 -> 0 | AL18: =Olawale_conf!I12*'scoring matrix'!J14-'GIR_conf '!I12*'scoring matrix'!J14 -> 0 | ... AP18: =Olawale_conf!M12*'scoring matrix'!N14-'GIR_conf '!M12*'scoring matrix'!N14 -> 0
B19: Basement | C19: =Olawale_conf!B30 -> 0 | D19: =Olawale_conf!C30 -> 0 | E19: =Olawale_conf!D30 -> 0 | F19: =Olawale_conf!E30 -> 0 | G19: =Olawale_conf!F30 -> 0 | H19: =Olawale_conf!G30 -> 0 | I19: =Olawale_conf!H30 -> 0 | J19: =Olawale_conf!I30 -> 0 | ... N19: =Olawale_conf!M30 -> 0 | P19: Basement | Q19: ='GIR_conf '!B30 -> 0 | R19: ='GIR_conf '!C30 -> 0 | S19: ='GIR_conf '!D30 -> 0 | T19: ='GIR_conf '!E30 -> 0 | U19: ='GIR_conf '!F30 -> 0 | V19: ='GIR_conf '!G30 -> 0 | W19: ='GIR_conf '!H30 -> 0 | X19: ='GIR_conf '!I30 -> 0 | ... AB19: ='GIR_conf '!M30 -> 0 | AD19: Basement | AE19: =Olawale_conf!B13*'scoring matrix'!C15-'GIR_conf '!B13*'scoring matrix'!C15 -> 0 | AF19: =Olawale_conf!C13*'scoring matrix'!D15-'GIR_conf '!C13*'scoring matrix'!D15 -> 0 | AG19: =Olawale_conf!D13*'scoring matrix'!E15-'GIR_conf '!D13*'scoring matrix'!E15 -> 0 | AH19: =Olawale_conf!E13*'scoring matrix'!F15-'GIR_conf '!E13*'scoring matrix'!F15 -> 0 | AI19: =Olawale_conf!F13*'scoring matrix'!G15-'GIR_conf '!F13*'scoring matrix'!G15 -> 0 | AJ19: =Olawale_conf!G13*'scoring matrix'!H15-'GIR_conf '!G13*'scoring matrix'!H15 -> 0 | AK19: =Olawale_conf!H13*'scoring matrix'!I15-'GIR_conf '!H13*'scoring matrix'!I15 -> 0 | AL19: =Olawale_conf!I13*'scoring matrix'!J15-'GIR_conf '!I13*'scoring matrix'!J15 -> 0 | ... AP19: =Olawale_conf!M13*'scoring matrix'!N15-'GIR_conf '!M13*'scoring matrix'!N15 -> 0
AE20: differential score olawale H3G
B21: 3rd ICA Predicted | C21: Labeled Sandstone | D21: Labeled Sandstone /Shale | E21: Labeled Shale | F21: Labeled Marls | G21: Labeled Dolomite | H21: Labeled Limestone | I21: Labeled Chalk | J21: Labeled Halite | K21: Labeled Anhydrite | L21: Labeled Tuff | M21: Labeled Coals | N21: Labeled Basement | P21: 4th H3G Predicted | Q21: Labeled Sandstone | R21: Labeled Sandstone /Shale | S21: Labeled Shale | T21: Labeled Marls | U21: Labeled Dolomite | V21: Labeled Limestone | W21: Labeled Chalk | X21: Labeled Halite | Y21: Labeled Anhydrite | Z21: Labeled Tuff | AA21: Labeled Coals | AB21: Labeled Basement | AD21: Olwale /H3G comparison | AE21: Labeled Sandstone | AF21: Labeled Sandstone /Shale | AG21: Labeled Shale | AH21: Labeled Marls | AI21: Labeled Dolomite | AJ21: Labeled Limestone | AK21: Labeled Chalk | AL21: Labeled Halite | AM21: Labeled Anhydrite | AN21: Labeled Tuff | AO21: Labeled Coals | AP21: Labeled Basement
B22: Sandstone | C22: =ICA_conf!B19 -> 71.284332 | D22: =ICA_conf!C19 -> 19.152821 | E22: =ICA_conf!D19 -> 2.3960588 | F22: =ICA_conf!E19 -> 8.6025691 | G22: =ICA_conf!F19 -> 0 | H22: =ICA_conf!G19 -> 7.5851551 | I22: =ICA_conf!H19 -> 0 | J22: =ICA_conf!I19 -> 0 | ... N22: =ICA_conf!M19 -> 0 | P22: Sandstone | Q22: =H3G_conf!B19 -> 79.455286 | R22: =H3G_conf!C19 -> 14.393679 | S22: =H3G_conf!D19 -> 2.34117 | T22: =H3G_conf!E19 -> 1.9991402 | U22: =H3G_conf!F19 -> 0 | V22: =H3G_conf!G19 -> 5.121652 | W22: =H3G_conf!H19 -> 0 | X22: =H3G_conf!I19 -> 0 | ... AB22: =H3G_conf!M19 -> 0 | AD22: Sandstone | AE22: =Olawale_conf!B2*'scoring matrix'!C4-H3G_conf!B2*'scoring matrix'!C4 -> 0 | AF22: =Olawale_conf!C2*'scoring matrix'!D4-H3G_conf!C2*'scoring matrix'!D4 -> 1772 | AG22: =Olawale_conf!D2*'scoring matrix'!E4-H3G_conf!D2*'scoring matrix'!E4 -> -2768.5 | AH22: =Olawale_conf!E2*'scoring matrix'!F4-H3G_conf!E2*'scoring matrix'!F4 -> 354 | AI22: =Olawale_conf!F2*'scoring matrix'!G4-H3G_conf!F2*'scoring matrix'!G4 -> 0 | AJ22: =Olawale_conf!G2*'scoring matrix'!H4-H3G_conf!G2*'scoring matrix'!H4 -> -941.5 | AK22: =Olawale_conf!H2*'scoring matrix'!I4-H3G_conf!H2*'scoring matrix'!I4 -> 0 | AL22: =Olawale_conf!I2*'scoring matrix'!J4-H3G_conf!I2*'scoring matrix'!J4 -> 0 | ... AP22: =Olawale_conf!M2*'scoring matrix'!N4-H3G_conf!M2*'scoring matrix'!N4 -> 0
B23: Sandstone /Shale | C23: =ICA_conf!B20 -> 15.123914 | D23: =ICA_conf!C20 -> 58.572211 | E23: =ICA_conf!D20 -> 8.2344306 | F23: =ICA_conf!E20 -> 2.9194239 | G23: =ICA_conf!F20 -> 0 | H23: =ICA_conf!G20 -> 0.74224708 | I23: =ICA_conf!H20 -> 0 | J23: =ICA_conf!I20 -> 0 | ... N23: =ICA_conf!M20 -> 0 | P23: Sandstone /Shale | Q23: =H3G_conf!B20 -> 11.723497 | R23: =H3G_conf!C20 -> 64.410855 | S23: =H3G_conf!D20 -> 10.109877 | T23: =H3G_conf!E20 -> 6.2983663 | U23: =H3G_conf!F20 -> 0 | V23: =H3G_conf!G20 -> 0.82805152 | W23: =H3G_conf!H20 -> 0 | X23: =H3G_conf!I20 -> 0 | ... AB23: =H3G_conf!M20 -> 0 | AD23: Sandstone /Shale | AE23: =Olawale_conf!B3*'scoring matrix'!C5-H3G_conf!B3*'scoring matrix'!C5 -> 348 | AF23: =Olawale_conf!C3*'scoring matrix'!D5-H3G_conf!C3*'scoring matrix'!D5 -> 0 | AG23: =Olawale_conf!D3*'scoring matrix'!E5-H3G_conf!D3*'scoring matrix'!E5 -> -3885.5 | AH23: =Olawale_conf!E3*'scoring matrix'!F5-H3G_conf!E3*'scoring matrix'!F5 -> -338.25 | AI23: =Olawale_conf!F3*'scoring matrix'!G5-H3G_conf!F3*'scoring matrix'!G5 -> 0 | AJ23: =Olawale_conf!G3*'scoring matrix'!H5-H3G_conf!G3*'scoring matrix'!H5 -> -210 | AK23: =Olawale_conf!H3*'scoring matrix'!I5-H3G_conf!H3*'scoring matrix'!I5 -> 0 | AL23: =Olawale_conf!I3*'scoring matrix'!J5-H3G_conf!I3*'scoring matrix'!J5 -> 0 | ... AP23: =Olawale_conf!M3*'scoring matrix'!N5-H3G_conf!M3*'scoring matrix'!N5 -> 0
B24: Shale | C24: =ICA_conf!B21 -> 4.7306362 | D24: =ICA_conf!C21 -> 12.908527 | E24: =ICA_conf!D21 -> 86.097634 | F24: =ICA_conf!E21 -> 22.148696 | G24: =ICA_conf!F21 -> 0 | H24: =ICA_conf!G21 -> 3.0299949 | I24: =ICA_conf!H21 -> 0.42492918 | J24: =ICA_conf!I21 -> 0.15253203 | ... N24: =ICA_conf!M21 -> 0 | P24: Shale | Q24: =H3G_conf!B21 -> 3.5742369 | R24: =H3G_conf!C21 -> 10.340089 | S24: =H3G_conf!D21 -> 83.999754 | T24: =H3G_conf!E21 -> 43.637145 | U24: =H3G_conf!F21 -> 0 | V24: =H3G_conf!G21 -> 3.1281946 | W24: =H3G_conf!H21 -> 3.343465 | X24: =H3G_conf!I21 -> 0.030926241 | ... AB24: =H3G_conf!M21 -> 0 | AD24: Shale | AE24: =Olawale_conf!B4*'scoring matrix'!C6-H3G_conf!B4*'scoring matrix'!C6 -> 56 | AF24: =Olawale_conf!C4*'scoring matrix'!D6-H3G_conf!C4*'scoring matrix'!D6 -> 1422.625 | AG24: =Olawale_conf!D4*'scoring matrix'!E6-H3G_conf!D4*'scoring matrix'!E6 -> 0 | AH24: =Olawale_conf!E4*'scoring matrix'!F6-H3G_conf!E4*'scoring matrix'!F6 -> -1538 | AI24: =Olawale_conf!F4*'scoring matrix'!G6-H3G_conf!F4*'scoring matrix'!G6 -> 0 | AJ24: =Olawale_conf!G4*'scoring matrix'!H6-H3G_conf!G4*'scoring matrix'!H6 -> -248.5 | AK24: =Olawale_conf!H4*'scoring matrix'!I6-H3G_conf!H4*'scoring matrix'!I6 -> -93.75 | AL24: =Olawale_conf!I4*'scoring matrix'!J6-H3G_conf!I4*'scoring matrix'!J6 -> 48 | ... AP24: =Olawale_conf!M4*'scoring matrix'!N6-H3G_conf!M4*'scoring matrix'!N6 -> 0
B25: Marl | C25: =ICA_conf!B22 -> 0.96024853 | D25: =ICA_conf!C22 -> 8.8004382 | E25: =ICA_conf!D22 -> 1.5563186 | F25: =ICA_conf!E22 -> 48.034255 | G25: =ICA_conf!F22 -> 0 | H25: =ICA_conf!G22 -> 12.841891 | I25: =ICA_conf!H22 -> 2.1246459 | J25: =ICA_conf!I22 -> 0 | ... N25: =ICA_conf!M22 -> 0 | P25: Marl | Q25: =H3G_conf!B22 -> 0.10722711 | R25: =H3G_conf!C22 -> 6.4926142 | S25: =H3G_conf!D22 -> 1.9384936 | T25: =H3G_conf!E22 -> 31.728289 | U25: =H3G_conf!F22 -> 0 | V25: =H3G_conf!G22 -> 10.611327 | W25: =H3G_conf!H22 -> 6.0182371 | X25: =H3G_conf!I22 -> 0 | ... AB25: =H3G_conf!M22 -> 0 | AD25: Marl | AE25: =Olawale_conf!B5*'scoring matrix'!C7-H3G_conf!B5*'scoring matrix'!C7 -> 6 | AF25: =Olawale_conf!C5*'scoring matrix'!D7-H3G_conf!C5*'scoring matrix'!D7 -> 827.75 | AG25: =Olawale_conf!D5*'scoring matrix'!E7-H3G_conf!D5*'scoring matrix'!E7 -> 100 | AH25: =Olawale_conf!E5*'scoring matrix'!F7-H3G_conf!E5*'scoring matrix'!F7 -> 0 | AI25: =Olawale_conf!F5*'scoring matrix'!G7-H3G_conf!F5*'scoring matrix'!G7 -> 0 | AJ25: =Olawale_conf!G5*'scoring matrix'!H7-H3G_conf!G5*'scoring matrix'!H7 -> -36 | AK25: =Olawale_conf!H5*'scoring matrix'!I7-H3G_conf!H5*'scoring matrix'!I7 -> -76.5 | AL25: =Olawale_conf!I5*'scoring matrix'!J7-H3G_conf!I5*'scoring matrix'!J7 -> 0 | ... AP25: =Olawale_conf!M5*'scoring matrix'!N7-H3G_conf!M5*'scoring matrix'!N7 -> 0
B26: Dolomite | C26: =ICA_conf!B23 -> 0.007060651 | D26: =ICA_conf!C23 -> 0 | E26: =ICA_conf!D23 -> 0.17914458 | F26: =ICA_conf!E23 -> 0.15570261 | G26: =ICA_conf!F23 -> 0 | H26: =ICA_conf!G23 -> 0.30503305 | I26: =ICA_conf!H23 -> 0 | J26: =ICA_conf!I23 -> 0.12202563 | ... N26: =ICA_conf!M23 -> 0 | P26: Dolomite | Q26: =H3G_conf!B23 -> 0.092930159 | R26: =H3G_conf!C23 -> 0 | S26: =H3G_conf!D23 -> 0.16696335 | T26: =H3G_conf!E23 -> 0.021496131 | U26: =H3G_conf!F23 -> 40 | V26: =H3G_conf!G23 -> 1.298303 | W26: =H3G_conf!H23 -> 0 | X26: =H3G_conf!I23 -> 0 | ... AB26: =H3G_conf!M23 -> 0 | AD26: Dolomite | AE26: =Olawale_conf!B6*'scoring matrix'!C8-H3G_conf!B6*'scoring matrix'!C8 -> -30 | AF26: =Olawale_conf!C6*'scoring matrix'!D8-H3G_conf!C6*'scoring matrix'!D8 -> 0 | AG26: =Olawale_conf!D6*'scoring matrix'!E8-H3G_conf!D6*'scoring matrix'!E8 -> 59.5 | AH26: =Olawale_conf!E6*'scoring matrix'!F8-H3G_conf!E6*'scoring matrix'!F8 -> 0 | AI26: =Olawale_conf!F6*'scoring matrix'!G8-H3G_conf!F6*'scoring matrix'!G8 -> 0 | AJ26: =Olawale_conf!G6*'scoring matrix'!H8-H3G_conf!G6*'scoring matrix'!H8 -> -309.75 | AK26: =Olawale_conf!H6*'scoring matrix'!I8-H3G_conf!H6*'scoring matrix'!I8 -> 0 | AL26: =Olawale_conf!I6*'scoring matrix'!J8-H3G_conf!I6*'scoring matrix'!J8 -> 7.5 | ... AP26: =Olawale_conf!M6*'scoring matrix'!N8-H3G_conf!M6*'scoring matrix'!N8 -> 0
B27: Limestone | C27: =ICA_conf!B24 -> 6.1780696 | D27: =ICA_conf!C24 -> 0.4929706 | E27: =ICA_conf!D24 -> 1.251524 | F27: =ICA_conf!E24 -> 18.100428 | G27: =ICA_conf!F24 -> 0 | H27: =ICA_conf!G24 -> 58.129131 | I27: =ICA_conf!H24 -> 17.13881 | J27: =ICA_conf!I24 -> 0 | ... N27: =ICA_conf!M24 -> 0 | P27: Limestone | Q27: =H3G_conf!B24 -> 3.6171277 | R27: =H3G_conf!C24 -> 4.0535898 | S27: =H3G_conf!D24 -> 1.0054631 | T27: =H3G_conf!E24 -> 16.16509 | U27: =H3G_conf!F24 -> 40 | V27: =H3G_conf!G24 -> 60.028624 | W27: =H3G_conf!H24 -> 16.595745 | X27: =H3G_conf!I24 -> 0 | ... AB27: =H3G_conf!M24 -> 0 | AD27: Limestone | AE27: =Olawale_conf!B7*'scoring matrix'!C9-H3G_conf!B7*'scoring matrix'!C9 -> 262.5 | AF27: =Olawale_conf!C7*'scoring matrix'!D9-H3G_conf!C7*'scoring matrix'!D9 -> 15 | AG27: =Olawale_conf!D7*'scoring matrix'!E9-H3G_conf!D7*'scoring matrix'!E9 -> 934.5 | AH27: =Olawale_conf!E7*'scoring matrix'!F9-H3G_conf!E7*'scoring matrix'!F9 -> 504 | AI27: =Olawale_conf!F7*'scoring matrix'!G9-H3G_conf!F7*'scoring matrix'!G9 -> 0 | AJ27: =Olawale_conf!G7*'scoring matrix'!H9-H3G_conf!G7*'scoring matrix'!H9 -> 0 | AK27: =Olawale_conf!H7*'scoring matrix'!I9-H3G_conf!H7*'scoring matrix'!I9 -> -101.75 | AL27: =Olawale_conf!I7*'scoring matrix'!J9-H3G_conf!I7*'scoring matrix'!J9 -> 0 | ... AP27: =Olawale_conf!M7*'scoring matrix'!N9-H3G_conf!M7*'scoring matrix'!N9 -> 0
B28: Chalk | C28: =ICA_conf!B25 -> 1.5251006 | D28: =ICA_conf!C25 -> 0 | E28: =ICA_conf!D25 -> 0.0012440596 | F28: =ICA_conf!E25 -> 0.038925652 | G28: =ICA_conf!F25 -> 0 | H28: =ICA_conf!G25 -> 15.790544 | I28: =ICA_conf!H25 -> 80.311615 | J28: =ICA_conf!I25 -> 0 | ... N28: =ICA_conf!M25 -> 0 | P28: Chalk | Q28: =H3G_conf!B25 -> 0.95074702 | R28: =H3G_conf!C25 -> 0 | S28: =H3G_conf!D25 -> 0.0012276717 | T28: =H3G_conf!E25 -> 0.10748065 | U28: =H3G_conf!F25 -> 0 | V28: =H3G_conf!G25 -> 15.824985 | W28: =H3G_conf!H25 -> 74.042553 | X28: =H3G_conf!I25 -> 0 | ... AB28: =H3G_conf!M25 -> 0 | AD28: Chalk | AE28: =Olawale_conf!B8*'scoring matrix'!C10-H3G_conf!B8*'scoring matrix'!C10 -> -196 | AF28: =Olawale_conf!C8*'scoring matrix'!D10-H3G_conf!C8*'scoring matrix'!D10 -> 0 | AG28: =Olawale_conf!D8*'scoring matrix'!E10-H3G_conf!D8*'scoring matrix'!E10 -> 0 | AH28: =Olawale_conf!E8*'scoring matrix'!F10-H3G_conf!E8*'scoring matrix'!F10 -> 2.25 | AI28: =Olawale_conf!F8*'scoring matrix'!G10-H3G_conf!F8*'scoring matrix'!G10 -> 0 | AJ28: =Olawale_conf!G8*'scoring matrix'!H10-H3G_conf!G8*'scoring matrix'!H10 -> 405.625 | AK28: =Olawale_conf!H8*'scoring matrix'!I10-H3G_conf!H8*'scoring matrix'!I10 -> 0 | AL28: =Olawale_conf!I8*'scoring matrix'!J10-H3G_conf!I8*'scoring matrix'!J10 -> 0 | ... AP28: =Olawale_conf!M8*'scoring matrix'!N10-H3G_conf!M8*'scoring matrix'!N10 -> 0
B29: Halite | C29: =ICA_conf!B26 -> 0 | D29: =ICA_conf!C26 -> 0 | E29: =ICA_conf!D26 -> 0.019904954 | F29: =ICA_conf!E26 -> 0 | G29: =ICA_conf!F26 -> 0 | H29: =ICA_conf!G26 -> 0.020335536 | I29: =ICA_conf!H26 -> 0 | J29: =ICA_conf!I26 -> 98.718731 | ... N29: =ICA_conf!M26 -> 0 | P29: Halite | Q29: =H3G_conf!B26 -> 0.042890843 | R29: =H3G_conf!C26 -> 0 | S29: =H3G_conf!D26 -> 0.054017556 | T29: =H3G_conf!E26 -> 0 | U29: =H3G_conf!F26 -> 0 | V29: =H3G_conf!G26 -> 0.081782866 | W29: =H3G_conf!H26 -> 0 | X29: =H3G_conf!I26 -> 99.242307 | ... AB29: =H3G_conf!M26 -> 0 | AD29: Halite | AE29: =Olawale_conf!B9*'scoring matrix'!C11-H3G_conf!B9*'scoring matrix'!C11 -> -24 | AF29: =Olawale_conf!C9*'scoring matrix'!D11-H3G_conf!C9*'scoring matrix'!D11 -> 0 | AG29: =Olawale_conf!D9*'scoring matrix'!E11-H3G_conf!D9*'scoring matrix'!E11 -> -92 | AH29: =Olawale_conf!E9*'scoring matrix'!F11-H3G_conf!E9*'scoring matrix'!F11 -> 0 | AI29: =Olawale_conf!F9*'scoring matrix'!G11-H3G_conf!F9*'scoring matrix'!G11 -> 18.75 | AJ29: =Olawale_conf!G9*'scoring matrix'!H11-H3G_conf!G9*'scoring matrix'!H11 -> -4 | AK29: =Olawale_conf!H9*'scoring matrix'!I11-H3G_conf!H9*'scoring matrix'!I11 -> 0 | AL29: =Olawale_conf!I9*'scoring matrix'!J11-H3G_conf!I9*'scoring matrix'!J11 -> 0 | ... AP29: =Olawale_conf!M9*'scoring matrix'!N11-H3G_conf!M9*'scoring matrix'!N11 -> 0
B30: Anhydrite | C30: =ICA_conf!B27 -> 0.091788463 | D30: =ICA_conf!C27 -> 0 | E30: =ICA_conf!D27 -> 0.029857431 | F30: =ICA_conf!E27 -> 0 | G30: =ICA_conf!F27 -> 0 | H30: =ICA_conf!G27 -> 1.3523132 | I30: =ICA_conf!H27 -> 0 | J30: =ICA_conf!I27 -> 1.0067114 | ... N30: =ICA_conf!M27 -> 0 | P30: Anhydrite | Q30: =H3G_conf!B27 -> 0.135821 | R30: =H3G_conf!C27 -> 0 | S30: =H3G_conf!D27 -> 0.024553434 | T30: =H3G_conf!E27 -> 0.042992261 | U30: =H3G_conf!F27 -> 20 | V30: =H3G_conf!G27 -> 2.8010632 | W30: =H3G_conf!H27 -> 0 | X30: =H3G_conf!I27 -> 0.72676666 | ... AB30: =H3G_conf!M27 -> 0 | AD30: Anhydrite | AE30: =Olawale_conf!B10*'scoring matrix'!C12-H3G_conf!B10*'scoring matrix'!C12 -> -4 | AF30: =Olawale_conf!C10*'scoring matrix'!D12-H3G_conf!C10*'scoring matrix'!D12 -> 0 | AG30: =Olawale_conf!D10*'scoring matrix'!E12-H3G_conf!D10*'scoring matrix'!E12 -> -52 | AH30: =Olawale_conf!E10*'scoring matrix'!F12-H3G_conf!E10*'scoring matrix'!F12 -> -8 | AI30: =Olawale_conf!F10*'scoring matrix'!G12-H3G_conf!F10*'scoring matrix'!G12 -> 29.25 | AJ30: =Olawale_conf!G10*'scoring matrix'!H12-H3G_conf!G10*'scoring matrix'!H12 -> -892.5 | AK30: =Olawale_conf!H10*'scoring matrix'!I12-H3G_conf!H10*'scoring matrix'!I12 -> 0 | AL30: =Olawale_conf!I10*'scoring matrix'!J12-H3G_conf!I10*'scoring matrix'!J12 -> 33 | ... AP30: =Olawale_conf!M10*'scoring matrix'!N12-H3G_conf!M10*'scoring matrix'!N12 -> 0
B31: Tuff | C31: =ICA_conf!B28 -> 0 | D31: =ICA_conf!C28 -> 0 | E31: =ICA_conf!D28 -> 0.19034112 | F31: =ICA_conf!E28 -> 0 | G31: =ICA_conf!F28 -> 0 | H31: =ICA_conf!G28 -> 0.20335536 | I31: =ICA_conf!H28 -> 0 | J31: =ICA_conf!I28 -> 0 | ... N31: =ICA_conf!M28 -> 0 | P31: Tuff | Q31: =H3G_conf!B28 -> 0 | R31: =H3G_conf!C28 -> 0.27481965 | S31: =H3G_conf!D28 -> 0.29709656 | T31: =H3G_conf!E28 -> 0 | U31: =H3G_conf!F28 -> 0 | V31: =H3G_conf!G28 -> 0.27601717 | W31: =H3G_conf!H28 -> 0 | X31: =H3G_conf!I28 -> 0 | ... AB31: =H3G_conf!M28 -> 0 | AD31: Tuff | AE31: =Olawale_conf!B11*'scoring matrix'!C13-H3G_conf!B11*'scoring matrix'!C13 -> 2.5 | AF31: =Olawale_conf!C11*'scoring matrix'!D13-H3G_conf!C11*'scoring matrix'!D13 -> -24 | AG31: =Olawale_conf!D11*'scoring matrix'!E13-H3G_conf!D11*'scoring matrix'!E13 -> -60.5 | AH31: =Olawale_conf!E11*'scoring matrix'!F13-H3G_conf!E11*'scoring matrix'!F13 -> 0 | AI31: =Olawale_conf!F11*'scoring matrix'!G13-H3G_conf!F11*'scoring matrix'!G13 -> 0 | AJ31: =Olawale_conf!G11*'scoring matrix'!H13-H3G_conf!G11*'scoring matrix'!H13 -> -63 | AK31: =Olawale_conf!H11*'scoring matrix'!I13-H3G_conf!H11*'scoring matrix'!I13 -> 0 | AL31: =Olawale_conf!I11*'scoring matrix'!J13-H3G_conf!I11*'scoring matrix'!J13 -> 0 | ... AP31: =Olawale_conf!M11*'scoring matrix'!N13-H3G_conf!M11*'scoring matrix'!N13 -> 0
B32: Coals | C32: =ICA_conf!B29 -> 0.098849114 | D32: =ICA_conf!C29 -> 0.073032682 | E32: =ICA_conf!D29 -> 0.043542087 | F32: =ICA_conf!E29 -> 0 | G32: =ICA_conf!F29 -> 0 | H32: =ICA_conf!G29 -> 0 | I32: =ICA_conf!H29 -> 0 | J32: =ICA_conf!I29 -> 0 | ... N32: =ICA_conf!M29 -> 0 | P32: Coals | Q32: =H3G_conf!B29 -> 0.3002359 | R32: =H3G_conf!C29 -> 0.034352456 | S32: =H3G_conf!D29 -> 0.061383586 | T32: =H3G_conf!E29 -> 0 | U32: =H3G_conf!F29 -> 0 | V32: =H3G_conf!G29 -> 0 | W32: =H3G_conf!H29 -> 0 | X32: =H3G_conf!I29 -> 0 | ... AB32: =H3G_conf!M29 -> 0 | AD32: Coals | AE32: =Olawale_conf!B12*'scoring matrix'!C14-H3G_conf!B12*'scoring matrix'!C14 -> -42.625 | AF32: =Olawale_conf!C12*'scoring matrix'!D14-H3G_conf!C12*'scoring matrix'!D14 -> 67.5 | AG32: =Olawale_conf!D12*'scoring matrix'!E14-H3G_conf!D12*'scoring matrix'!E14 -> 6.5 | AH32: =Olawale_conf!E12*'scoring matrix'!F14-H3G_conf!E12*'scoring matrix'!F14 -> 0 | AI32: =Olawale_conf!F12*'scoring matrix'!G14-H3G_conf!F12*'scoring matrix'!G14 -> 0 | AJ32: =Olawale_conf!G12*'scoring matrix'!H14-H3G_conf!G12*'scoring matrix'!H14 -> 8 | AK32: =Olawale_conf!H12*'scoring matrix'!I14-H3G_conf!H12*'scoring matrix'!I14 -> 0 | AL32: =Olawale_conf!I12*'scoring matrix'!J14-H3G_conf!I12*'scoring matrix'!J14 -> 0 | ... AP32: =Olawale_conf!M12*'scoring matrix'!N14-H3G_conf!M12*'scoring matrix'!N14 -> 0
B33: Basement | C33: =ICA_conf!B30 -> 0 | D33: =ICA_conf!C30 -> 0 | E33: =ICA_conf!D30 -> 0 | F33: =ICA_conf!E30 -> 0 | G33: =ICA_conf!F30 -> 0 | H33: =ICA_conf!G30 -> 0 | I33: =ICA_conf!H30 -> 0 | J33: =ICA_conf!I30 -> 0 | ... N33: =ICA_conf!M30 -> 0 | P33: Basement | Q33: =H3G_conf!B30 -> 0 | R33: =H3G_conf!C30 -> 0 | S33: =H3G_conf!D30 -> 0 | T33: =H3G_conf!E30 -> 0 | U33: =H3G_conf!F30 -> 0 | V33: =H3G_conf!G30 -> 0 | W33: =H3G_conf!H30 -> 0 | X33: =H3G_conf!I30 -> 0 | ... AB33: =H3G_conf!M30 -> 0 | AD33: Basement | AE33: =Olawale_conf!B13*'scoring matrix'!C15-H3G_conf!B13*'scoring matrix'!C15 -> 0 | AF33: =Olawale_conf!C13*'scoring matrix'!D15-H3G_conf!C13*'scoring matrix'!D15 -> 0 | AG33: =Olawale_conf!D13*'scoring matrix'!E15-H3G_conf!D13*'scoring matrix'!E15 -> 0 | AH33: =Olawale_conf!E13*'scoring matrix'!F15-H3G_conf!E13*'scoring matrix'!F15 -> 0 | AI33: =Olawale_conf!F13*'scoring matrix'!G15-H3G_conf!F13*'scoring matrix'!G15 -> 0 | AJ33: =Olawale_conf!G13*'scoring matrix'!H15-H3G_conf!G13*'scoring matrix'!H15 -> 0 | AK33: =Olawale_conf!H13*'scoring matrix'!I15-H3G_conf!H13*'scoring matrix'!I15 -> 0 | AL33: =Olawale_conf!I13*'scoring matrix'!J15-H3G_conf!I13*'scoring matrix'!J15 -> 0 | ... AP33: =Olawale_conf!M13*'scoring matrix'!N15-H3G_conf!M13*'scoring matrix'!N15 -> 0
B35: 5th Ispl Predicted | C35: Labeled Sandstone | D35: Labeled Sandstone /Shale | E35: Labeled Shale | F35: Labeled Marls | G35: Labeled Dolomite | H35: Labeled Limestone | I35: Labeled Chalk | J35: Labeled Halite | K35: Labeled Anhydrite | L35: Labeled Tuff | M35: Labeled Coals | N35: Labeled Basement
B36: Sandstone | C36: =ISPL_conf!B19 -> 67.792636 | D36: =ISPL_conf!C19 -> 30.673383 | E36: =ISPL_conf!D19 -> 0.94000263 | F36: =ISPL_conf!E19 -> 4.6087617 | G36: =ISPL_conf!F19 -> 0 | H36: =ISPL_conf!G19 -> 1.5274034 | I36: =ISPL_conf!H19 -> 0 | J36: =ISPL_conf!I19 -> 0 | ... N36: =ISPL_conf!M19 -> 0
B37: Sandstone /Shale | C37: =ISPL_conf!B20 -> 18.505609 | D37: =ISPL_conf!C20 -> 47.150053 | E37: =ISPL_conf!D20 -> 7.0789025 | F37: =ISPL_conf!E20 -> 7.8247658 | G37: =ISPL_conf!F20 -> 0 | H37: =ISPL_conf!G20 -> 0.66262354 | I37: =ISPL_conf!H20 -> 0 | J37: =ISPL_conf!I20 -> 0 | ... N37: =ISPL_conf!M20 -> 0
B38: Shale | C38: =ISPL_conf!B21 -> 7.6430699 | D38: =ISPL_conf!C21 -> 17.948038 | E38: =ISPL_conf!D21 -> 87.819351 | F38: =ISPL_conf!E21 -> 43.302102 | G38: =ISPL_conf!F21 -> 4.4897959 | H38: =ISPL_conf!G21 -> 3.5377358 | I38: =ISPL_conf!H21 -> 0 | J38: =ISPL_conf!I21 -> 0.16804155 | ... N38: =ISPL_conf!M21 -> 0
B39: Marl | C39: =ISPL_conf!B22 -> 0.17745104 | D39: =ISPL_conf!C22 -> 2.4655355 | E39: =ISPL_conf!D22 -> 2.5141132 | F39: =ISPL_conf!E22 -> 24.537858 | G39: =ISPL_conf!F22 -> 2.8571429 | H39: =ISPL_conf!G22 -> 14.049865 | I39: =ISPL_conf!H22 -> 2.1810251 | J39: =ISPL_conf!I22 -> 0 | ... N39: =ISPL_conf!M22 -> 0
B40: Dolomite | C40: =ISPL_conf!B23 -> 0.063375372 | D40: =ISPL_conf!C23 -> 0.17232238 | E40: =ISPL_conf!D23 -> 0.27307339 | F40: =ISPL_conf!E23 -> 0.025322867 | G40: =ISPL_conf!F23 -> 0 | H40: =ISPL_conf!G23 -> 0.3032345 | I40: =ISPL_conf!H23 -> 0 | J40: =ISPL_conf!I23 -> 0.030553009 | ... N40: =ISPL_conf!M23 -> 0
B41: Limestone | C41: =ISPL_conf!B24 -> 4.7785031 | D41: =ISPL_conf!C24 -> 1.1664899 | E41: =ISPL_conf!D24 -> 0.93606407 | F41: =ISPL_conf!E24 -> 17.270195 | G41: =ISPL_conf!F24 -> 55.918367 | H41: =ISPL_conf!G24 -> 60.017969 | I41: =ISPL_conf!H24 -> 34.896401 | J41: =ISPL_conf!I24 -> 0 | ... N41: =ISPL_conf!M24 -> 0
B42: Chalk | C42: =ISPL_conf!B25 -> 0.031687686 | D42: =ISPL_conf!C25 -> 0 | E42: =ISPL_conf!D25 -> 0 | F42: =ISPL_conf!E25 -> 2.4309952 | G42: =ISPL_conf!F25 -> 0 | H42: =ISPL_conf!G25 -> 18.530997 | I42: =ISPL_conf!H25 -> 62.922574 | J42: =ISPL_conf!I25 -> 0 | ... N42: =ISPL_conf!M25 -> 0
B43: Halite | C43: =ISPL_conf!B26 -> 0.18378858 | D43: =ISPL_conf!C26 -> 0.092788971 | E43: =ISPL_conf!D26 -> 0.014441381 | F43: =ISPL_conf!E26 -> 0 | G43: =ISPL_conf!F26 -> 0 | H43: =ISPL_conf!G26 -> 0.011230907 | I43: =ISPL_conf!H26 -> 0 | J43: =ISPL_conf!I26 -> 98.411244 | ... N43: =ISPL_conf!M26 -> 0
B44: Anhydrite | C44: =ISPL_conf!B27 -> 0.14576336 | D44: =ISPL_conf!C27 -> 0 | E44: =ISPL_conf!D27 -> 0.010502823 | F44: =ISPL_conf!E27 -> 0 | G44: =ISPL_conf!F27 -> 36.734694 | H44: =ISPL_conf!G27 -> 1.0107817 | I44: =ISPL_conf!H27 -> 0 | J44: =ISPL_conf!I27 -> 1.3901619 | ... N44: =ISPL_conf!M27 -> 0
B45: Tuff | C45: =ISPL_conf!B28 -> 0.57671589 | D45: =ISPL_conf!C28 -> 0.21208908 | E45: =ISPL_conf!D28 -> 0.37416306 | F45: =ISPL_conf!E28 -> 0 | G45: =ISPL_conf!F28 -> 0 | H45: =ISPL_conf!G28 -> 0.34815813 | I45: =ISPL_conf!H28 -> 0 | J45: =ISPL_conf!I28 -> 0 | ... N45: =ISPL_conf!M28 -> 0
B46: Coals | C46: =ISPL_conf!B29 -> 0.1014006 | D46: =ISPL_conf!C29 -> 0.11930011 | E46: =ISPL_conf!D29 -> 0.039385585 | F46: =ISPL_conf!E29 -> 0 | G46: =ISPL_conf!F29 -> 0 | H46: =ISPL_conf!G29 -> 0 | I46: =ISPL_conf!H29 -> 0 | J46: =ISPL_conf!I29 -> 0 | ... N46: =ISPL_conf!M29 -> 0
...

Sheet DavidP_conf
B1: Labeled Sandstone | C1: Labeled Sandstone /Shale | D1: Labeled Shale | E1: Labeled Marls | F1: Labeled Dolomite | G1: Labeled Limestone | H1: Labeled Chalk | I1: Labeled Halite | J1: Labeled Anhydrite | K1: Labeled Tuff | L1: Labeled Coals | M1: Labeled Basement
A2: Predicted | B2: 10915 | C2: 1499 | D2: 1248 | E2: 101 | F2: 0 | G2: 277 | H2: 0 | I2: 0 | J2: 0 | K2: 5 | L2: 0 | M2: 0 | O2: =SUM(B2:M13) -> 122397 | R2: =B2/$O$2*100 -> 8.9177022 | S2: =C2/$O$2*100 -> 1.2247032 | T2: =D2/$O$2*100 -> 1.0196328 | U2: =E2/$O$2*100 -> 0.082518362 | V2: =F2/$O$2*100 -> 0 | W2: =G2/$O$2*100 -> 0.22631274 | X2: =H2/$O$2*100 -> 0 | Y2: =I2/$O$2*100 -> 0 | ... AC2: =M2/$O$2*100 -> 0
A3: Sandstone | B3: 2268 | C3: 3674 | D3: 6018 | E3: 136 | F3: 0 | G3: 58 | H3: 0 | I3: 0 | J3: 0 | K3: 102 | L3: 27 | M3: 0 | R3: =B3/$O$2*100 -> 1.8529866 | S3: =C3/$O$2*100 -> 3.0017076 | T3: =D3/$O$2*100 -> 4.9167872 | U3: =E3/$O$2*100 -> 0.11111383 | V3: =F3/$O$2*100 -> 0 | W3: =G3/$O$2*100 -> 0.047386782 | X3: =H3/$O$2*100 -> 0 | Y3: =I3/$O$2*100 -> 0 | ... AC3: =M3/$O$2*100 -> 0
A4: Sandstone /Shale | B4: 303 | C4: 2331 | D4: 67989 | E4: 619 | F4: 0 | G4: 363 | H4: 0 | I4: 0 | J4: 0 | K4: 190 | L4: 32 | M4: 0 | R4: =B4/$O$2*100 -> 0.24755509 | S4: =C4/$O$2*100 -> 1.9044584 | T4: =D4/$O$2*100 -> 55.54793 | U4: =E4/$O$2*100 -> 0.50573135 | V4: =F4/$O$2*100 -> 0 | W4: =G4/$O$2*100 -> 0.2965759 | X4: =H4/$O$2*100 -> 0 | Y4: =I4/$O$2*100 -> 0 | ... AC4: =M4/$O$2*100 -> 0
A5: Shale | B5: 14 | C5: 107 | D5: 2125 | E5: 831 | F5: 0 | G5: 1318 | H5: 1 | I5: 0 | J5: 0 | K5: 0 | L5: 0 | M5: 0 | R5: =B5/$O$2*100 -> 0.011438189 | S5: =C5/$O$2*100 -> 0.087420443 | T5: =D5/$O$2*100 -> 1.7361537 | U5: =E5/$O$2*100 -> 0.67893821 | V5: =F5/$O$2*100 -> 0 | W5: =G5/$O$2*100 -> 1.0768238 | X5: =H5/$O$2*100 -> 0.00081701349 | Y5: =I5/$O$2*100 -> 0 | ... AC5: =M5/$O$2*100 -> 0
A6: Marl | B6: 0 | C6: 0 | D6: 202 | E6: 0 | F6: 0 | G6: 30 | H6: 0 | I6: 1 | J6: 0 | K6: 0 | L6: 54 | M6: 0 | R6: =B6/$O$2*100 -> 0 | S6: =C6/$O$2*100 -> 0 | T6: =D6/$O$2*100 -> 0.16503672 | U6: =E6/$O$2*100 -> 0 | V6: =F6/$O$2*100 -> 0 | W6: =G6/$O$2*100 -> 0.024510405 | X6: =H6/$O$2*100 -> 0 | Y6: =I6/$O$2*100 -> 0.00081701349 | ... AC6: =M6/$O$2*100 -> 0
A7: Dolomite | B7: 567 | C7: 23 | D7: 1102 | E7: 495 | F7: 0 | G7: 6158 | H7: 0 | I7: 0 | J7: 0 | K7: 29 | L7: 0 | M7: 0 | R7: =B7/$O$2*100 -> 0.46324665 | S7: =C7/$O$2*100 -> 0.01879131 | T7: =D7/$O$2*100 -> 0.90034886 | U7: =E7/$O$2*100 -> 0.40442168 | V7: =F7/$O$2*100 -> 0 | W7: =G7/$O$2*100 -> 5.0311691 | X7: =H7/$O$2*100 -> 0 | Y7: =I7/$O$2*100 -> 0 | ... AC7: =M7/$O$2*100 -> 0
A8: Limestone | B8: 136 | C8: 0 | D8: 25 | E8: 4 | F8: 0 | G8: 2491 | H8: 249 | I8: 0 | J8: 0 | K8: 0 | L8: 0 | M8: 0 | R8: =B8/$O$2*100 -> 0.11111383 | S8: =C8/$O$2*100 -> 0 | T8: =D8/$O$2*100 -> 0.020425337 | U8: =E8/$O$2*100 -> 0.003268054 | V8: =F8/$O$2*100 -> 0 | W8: =G8/$O$2*100 -> 2.0351806 | X8: =H8/$O$2*100 -> 0.20343636 | Y8: =I8/$O$2*100 -> 0 | ... AC8: =M8/$O$2*100 -> 0
A9: Chalk | B9: 0 | C9: 0 | D9: 81 | E9: 0 | F9: 0 | G9: 660 | H9: 0 | I9: 5756 | J9: 0 | K9: 0 | L9: 1 | M9: 0 | R9: =B9/$O$2*100 -> 0 | S9: =C9/$O$2*100 -> 0 | T9: =D9/$O$2*100 -> 0.066178093 | U9: =E9/$O$2*100 -> 0 | V9: =F9/$O$2*100 -> 0 | W9: =G9/$O$2*100 -> 0.5392289 | X9: =H9/$O$2*100 -> 0 | Y9: =I9/$O$2*100 -> 4.7027296 | ... AC9: =M9/$O$2*100 -> 0
A10: Halite | B10: 8 | C10: 3 | D10: 25 | E10: 0 | F10: 0 | G10: 249 | H10: 0 | I10: 56 | J10: 0 | K10: 0 | L10: 256 | M10: 0 | R10: =B10/$O$2*100 -> 0.0065361079 | S10: =C10/$O$2*100 -> 0.0024510405 | T10: =D10/$O$2*100 -> 0.020425337 | U10: =E10/$O$2*100 -> 0 | V10: =F10/$O$2*100 -> 0 | W10: =G10/$O$2*100 -> 0.20343636 | X10: =H10/$O$2*100 -> 0 | Y10: =I10/$O$2*100 -> 0.045752755 | ... AC10: =M10/$O$2*100 -> 0
A11: Anhydrite | B11: 114 | C11: 0 | D11: 379 | E11: 0 | F11: 0 | G11: 38 | H11: 0 | I11: 0 | J11: 0 | K11: 410 | L11: 0 | M11: 0 | R11: =B11/$O$2*100 -> 0.093139538 | S11: =C11/$O$2*100 -> 0 | T11: =D11/$O$2*100 -> 0.30964811 | U11: =E11/$O$2*100 -> 0 | V11: =F11/$O$2*100 -> 0 | W11: =G11/$O$2*100 -> 0.031046513 | X11: =H11/$O$2*100 -> 0 | Y11: =I11/$O$2*100 -> 0 | ... AC11: =M11/$O$2*100 -> 0
A12: Tuff | B12: 18 | C12: 8 | D12: 25 | E12: 0 | F12: 0 | G12: 0 | H12: 0 | I12: 0 | J12: 0 | K12: 0 | L12: 193 | M12: 0 | R12: =B12/$O$2*100 -> 0.014706243 | S12: =C12/$O$2*100 -> 0.0065361079 | T12: =D12/$O$2*100 -> 0.020425337 | U12: =E12/$O$2*100 -> 0 | V12: =F12/$O$2*100 -> 0 | W12: =G12/$O$2*100 -> 0 | X12: =H12/$O$2*100 -> 0 | Y12: =I12/$O$2*100 -> 0 | ... AC12: =M12/$O$2*100 -> 0
A13: Coals | B13: 0 | C13: 0 | D13: 0 | E13: 0 | F13: 0 | G13: 0 | H13: 0 | I13: 0 | J13: 0 | K13: 0 | L13: 0 | M13: 0 | R13: =B13/$O$2*100 -> 0 | S13: =C13/$O$2*100 -> 0 | T13: =D13/$O$2*100 -> 0 | U13: =E13/$O$2*100 -> 0 | V13: =F13/$O$2*100 -> 0 | W13: =G13/$O$2*100 -> 0 | X13: =H13/$O$2*100 -> 0 | Y13: =I13/$O$2*100 -> 0 | ... AC13: =M13/$O$2*100 -> 0
A14: Basement
B16: Percentage David P
A18: Predicted | B18: Labeled Sandstone | C18: Labeled Sandstone /Shale | D18: Labeled Shale | E18: Labeled Marls | F18: Labeled Dolomite | G18: Labeled Limestone | H18: Labeled Chalk | I18: Labeled Halite | J18: Labeled Anhydrite | K18: Labeled Tuff | L18: Labeled Coals | M18: Labeled Basement
